<?xml version="1.0" ?>
<!-- =================================================================================== -->
<!-- |    This document was autogenerated by xacro from robot_006.xacro                | -->
<!-- |    EDITING THIS FILE BY HAND IS NOT RECOMMENDED                                 | -->
<!-- =================================================================================== -->
<!-- This URDF was automatically created by SolidWorks to URDF Exporter! Originally created by Stephen Brawner (brawner@gmail.com) 
     Commit Version: 1.6.0-4-g7f85cfe  Build Version: 1.6.7995.38578
     For more information, please see http://wiki.ros.org/sw_urdf_exporter -->
<robot name="robot_006">
  <gazebo>
    <plugin filename="libgazebo_ros_control.so" name="gazebo_ros_control">
      <robotNamespace>robot_006</robotNamespace>
      <robotSimType>gazebo_ros_control/DefaultRobotHWSim</robotSimType>
    </plugin>
  </gazebo>
  <!-- hokuyo -->
  <gazebo reference="lidar_link">
    <sensor name="head_lidar_sensor" type="ray">
      <pose>0 0 0 0 0 0</pose>
      <visualize>true</visualize>
      <update_rate>40</update_rate>
      <ray>
        <scan>
          <horizontal>
            <samples>720</samples>
            <resolution>1</resolution>
            <min_angle>-3.14</min_angle>
            <max_angle>3.14</max_angle>
          </horizontal>
        </scan>
        <range>
          <min>0.10</min>
          <max>30.0</max>
          <resolution>0.01</resolution>
        </range>
        <noise>
          <type>gaussian</type>
          <!-- Noise parameters based on published spec for Hokuyo laser
               achieving "+-30mm" accuracy at range < 10m.  A mean of 0.0m and
               stddev of 0.01m will put 99.7% of samples within 0.03m of the true
               reading. -->
          <mean>0.0</mean>
          <stddev>0.01</stddev>
        </noise>
      </ray>
      <plugin filename="libgazebo_ros_laser.so" name="gazebo_ros_head_lidar_controller">
        <topicName>/robot_006/laser/scan</topicName>
        <frameName>lidar_link</frameName>
      </plugin>
    </sensor>
  </gazebo>
  <gazebo reference="base_link">
    <material>Gazebo/Blue</material>
  </gazebo>
  <gazebo reference="lidar_link">
    <material>Gazebo/Black</material>
  </gazebo>
  <gazebo reference="Left_wheel_03_link">
    <material>Gazebo/Black</material>
  </gazebo>
  <gazebo reference="Right_wheel_03_link">
    <material>Gazebo/Black</material>
  </gazebo>
  <gazebo>
    <plugin filename="libgazebo_ros_skid_steer_drive.so" name="skid_steer_drive">
      <updateRate>500</updateRate>
      <leftFrontJoint>Left_wheel_03_link</leftFrontJoint>
      <rightFrontJoint>Right_wheel_03_link</rightFrontJoint>
      <leftRearJoint>Left_wheel_01_link</leftRearJoint>
      <rightRearJoint>Right_wheel_01_link</rightRearJoint>
      <wheelSeparation>1.25</wheelSeparation>
      <wheelDiameter>0.3</wheelDiameter>
      <torque>20</torque>
      <commandTopic>cmd_demo</commandTopic>
      <odometryTopic>odom_demo</odometryTopic>
      <odometryFrame>odom_demo</odometryFrame>
      <broadcastTF>true</broadcastTF>
    </plugin>
  </gazebo>
  <link name="base_link">
    <inertial>
      <origin rpy="0 0 0" xyz="0.0028535 0.34369 0.067012"/>
      <mass value="6.3834"/>
      <inertia ixx="0.34574" ixy="2.7545E-05" ixz="4.4178E-16" iyy="0.37646" iyz="6.8636E-16" izz="0.30569"/>
    </inertial>
    <visual>
      <origin rpy="0 0 0" xyz="0 0 0"/>
      <geometry>
        <mesh filename="package://robot_006/robot_006_description/meshes/base_link.STL"/>
      </geometry>
      <material name="black">
        <color rgba="0.49804 0.49804 0.49804 1"/>
        <texture filename="package://robot_006/robot_006_description/textures/black.jpg"/>
      </material>
    </visual>
    <collision>
      <origin rpy="0 0 0" xyz="0 0 0"/>
      <geometry>
        <mesh filename="package://robot_006/robot_006_description/meshes/base_link.STL"/>
      </geometry>
    </collision>
  </link>
  <link name="left_wheel_01_link">
    <inertial>
      <origin rpy="0 0 0" xyz="0.0810455771702411 -8.67361737988404E-18 0"/>
      <mass value="7.38632836745033"/>
      <inertia ixx="0.0208460115156416" ixy="-7.30031821441943E-19" ixz="1.40926829579469E-18" iyy="0.0121153656310422" iyz="-7.58941520739853E-19" izz="0.0121153656310422"/>
    </inertial>
    <visual>
      <origin rpy="0 0 0" xyz="0 0 0"/>
      <geometry>
        <mesh filename="package://robot_006/robot_006_description/meshes/left_wheel_01_link.STL"/>
      </geometry>
      <material name="">
        <color rgba="0.792156862745098 0.819607843137255 0.933333333333333 1"/>
      </material>
    </visual>
    <collision>
      <origin rpy="0 0 0" xyz="0 0 0"/>
      <geometry>
        <mesh filename="package://robot_006/robot_006_description/meshes/left_wheel_01_link.STL"/>
      </geometry>
    </collision>
  </link>
  <joint name="Left_wheel_01_link" type="continuous">
    <origin rpy="1.6176 0 3.1416" xyz="-0.18382 0.21 0"/>
    <parent link="base_link"/>
    <child link="left_wheel_01_link"/>
    <axis xyz="1 0 0"/>
  </joint>
  <link name="left_wheel_02_link">
    <inertial>
      <origin rpy="0 0 0" xyz="0.0810455771702411 2.87112417300684E-19 1.17130577147236E-17"/>
      <mass value="7.38632836745033"/>
      <inertia ixx="0.0208460115156416" ixy="-5.32200053630169E-19" ixz="1.69064860125389E-18" iyy="0.0121153656310422" iyz="2.16840434497101E-18" izz="0.0121153656310422"/>
    </inertial>
    <visual>
      <origin rpy="0 0 0" xyz="0 0 0"/>
      <geometry>
        <mesh filename="package://robot_006/robot_006_description/meshes/left_wheel_02_link.STL"/>
      </geometry>
      <material name="">
        <color rgba="0.792156862745098 0.819607843137255 0.933333333333333 1"/>
      </material>
    </visual>
    <collision>
      <origin rpy="0 0 0" xyz="0 0 0"/>
      <geometry>
        <mesh filename="package://robot_006/robot_006_description/meshes/left_wheel_02_link.STL"/>
      </geometry>
    </collision>
  </link>
  <joint name="Left_wheel_02_link" type="continuous">
    <origin rpy="2.4353 0 -3.1416" xyz="-0.18382 0 0"/>
    <parent link="base_link"/>
    <child link="left_wheel_02_link"/>
    <axis xyz="1 0 0"/>
  </joint>
  <link name="left_wheel_03_link">
    <inertial>
      <origin rpy="0 0 0" xyz="0.0810455771702411 0 -5.55111512312578E-17"/>
      <mass value="7.38632836745033"/>
      <inertia ixx="0.0208460115156416" ixy="1.42504187367709E-19" ixz="-2.9721660450084E-19" iyy="0.0121153656310422" iyz="0" izz="0.0121153656310422"/>
    </inertial>
    <visual>
      <origin rpy="0 0 0" xyz="0 0 0"/>
      <geometry>
        <mesh filename="package://robot_006/robot_006_description/meshes/left_wheel_03_link.STL"/>
      </geometry>
      <material name="">
        <color rgba="0.792156862745098 0.819607843137255 0.933333333333333 1"/>
      </material>
    </visual>
    <collision>
      <origin rpy="0 0 0" xyz="0 0 0"/>
      <geometry>
        <mesh filename="package://robot_006/robot_006_description/meshes/left_wheel_03_link.STL"/>
      </geometry>
    </collision>
  </link>
  <joint name="Left_wheel_03_link" type="continuous">
    <origin rpy="1.6982 0 3.1416" xyz="-0.18382 -0.21 0"/>
    <parent link="base_link"/>
    <child link="left_wheel_03_link"/>
    <axis xyz="1 0 0"/>
  </joint>
  <link name="right_wheel_01_link">
    <inertial>
      <origin rpy="0 0 0" xyz="0.0810455771702411 -1.33465102787837E-18 0"/>
      <mass value="7.38632836745033"/>
      <inertia ixx="0.0208460115156416" ixy="4.04941442896144E-19" ixz="5.05940785059499E-19" iyy="0.0121153656310422" iyz="-1.3156256345534E-18" izz="0.0121153656310422"/>
    </inertial>
    <visual>
      <origin rpy="0 0 0" xyz="0 0 0"/>
      <geometry>
        <mesh filename="package://robot_006/robot_006_description/meshes/right_wheel_01_link.STL"/>
      </geometry>
      <material name="">
        <color rgba="0.792156862745098 0.819607843137255 0.933333333333333 1"/>
      </material>
    </visual>
    <collision>
      <origin rpy="0 0 0" xyz="0 0 0"/>
      <geometry>
        <mesh filename="package://robot_006/robot_006_description/meshes/right_wheel_01_link.STL"/>
      </geometry>
    </collision>
  </link>
  <joint name="Right_wheel_01_link" type="continuous">
    <origin rpy="1.5708 0 0" xyz="0.18382 0.21 0"/>
    <parent link="base_link"/>
    <child link="right_wheel_01_link"/>
    <axis xyz="1 0 0"/>
  </joint>
  <link name="right_wheel_02_link">
    <inertial>
      <origin rpy="0 0 0" xyz="0.081045577170241 -1.33465102787837E-18 2.94364146830802E-19"/>
      <mass value="7.38632836745033"/>
      <inertia ixx="0.0208460115156416" ixy="4.04941442896144E-19" ixz="5.05940785059499E-19" iyy="0.0121153656310422" iyz="-1.3156256345534E-18" izz="0.0121153656310422"/>
    </inertial>
    <visual>
      <origin rpy="0 0 0" xyz="0 0 0"/>
      <geometry>
        <mesh filename="package://robot_006/robot_006_description/meshes/right_wheel_02_link.STL"/>
      </geometry>
      <material name="">
        <color rgba="0.792156862745098 0.819607843137255 0.933333333333333 1"/>
      </material>
    </visual>
    <collision>
      <origin rpy="0 0 0" xyz="0 0 0"/>
      <geometry>
        <mesh filename="package://robot_006/robot_006_description/meshes/right_wheel_02_link.STL"/>
      </geometry>
    </collision>
  </link>
  <joint name="Right_wheel_02_link" type="continuous">
    <origin rpy="1.5708 0 0" xyz="0.18382 0 0"/>
    <parent link="base_link"/>
    <child link="right_wheel_02_link"/>
    <axis xyz="1 0 0"/>
  </joint>
  <link name="right_wheel_03_link">
    <inertial>
      <origin rpy="0 0 0" xyz="0.0810455771702411 -2.77555756156289E-17 5.55111512312578E-17"/>
      <mass value="7.38632836745033"/>
      <inertia ixx="0.0208460115156416" ixy="2.044350574312E-19" ixz="-1.00448384628692E-18" iyy="0.0121153656310422" iyz="2.60208521396521E-18" izz="0.0121153656310422"/>
    </inertial>
    <visual>
      <origin rpy="0 0 0" xyz="0 0 0"/>
      <geometry>
        <mesh filename="package://robot_006/robot_006_description/meshes/right_wheel_03_link.STL"/>
      </geometry>
      <material name="">
        <color rgba="0.792156862745098 0.819607843137255 0.933333333333333 1"/>
      </material>
    </visual>
    <collision>
      <origin rpy="0 0 0" xyz="0 0 0"/>
      <geometry>
        <mesh filename="package://robot_006/robot_006_description/meshes/right_wheel_03_link.STL"/>
      </geometry>
    </collision>
  </link>
  <joint name="Right_wheel_03_link" type="continuous">
    <origin rpy="1.3303 0 0" xyz="0.18382 -0.21 0"/>
    <parent link="base_link"/>
    <child link="right_wheel_03_link"/>
    <axis xyz="1 0 0"/>
  </joint>
  <link name="lidar_link">
    <inertial>
      <origin rpy="0 0 0" xyz="5.13755296872079E-17 -1.20842733323598E-17 -0.639080780507335"/>
      <mass value="0.491430460551325"/>
      <inertia ixx="0.000499328268367785" ixy="-1.20370621524202E-35" ixz="-1.59325678180355E-20" iyy="0.000499328268367785" iyz="-2.69786365718604E-36" izz="0.000517286112813611"/>
    </inertial>
    <visual>
      <origin rpy="0 0 0" xyz="0 0 0"/>
      <geometry>
        <mesh filename="package://robot_006/robot_006_description/meshes/lidar_link.STL"/>
      </geometry>
      <material name="">
        <color rgba="0 0 0 1"/>
      </material>
    </visual>
    <collision>
      <origin rpy="0 0 0" xyz="0 0 0"/>
      <geometry>
        <mesh filename="package://robot_006/robot_006_description/meshes/lidar_link.STL"/>
      </geometry>
    </collision>
  </link>
  <joint name="Lidar_link" type="fixed">
    <origin rpy="3.1416 0 1.5708" xyz="0 0 0"/>
    <parent link="base_link"/>
    <child link="lidar_link"/>
    <axis xyz="0 0 1"/>
  </joint>
  <!--
    <transmission name="tran1">
    <type>transmission_interface/SimpleTransmission</type>
    <joint name="Right_wheel_03_link">
      <hardwareInterface>EffortJointInterface</hardwareInterface>
    </joint>
    <actuator name="motor1">
      <hardwareInterface>EffortJointInterface</hardwareInterface>
      <mechanicalReduction>1</mechanicalReduction>
    </actuator>
  </transmission>
  <transmission name="tran2">
    <type>transmission_interface/SimpleTransmission</type>
    <joint name="Right_wheel_01_link">
      <hardwareInterface>EffortJointInterface</hardwareInterface>
    </joint>
    <actuator name="motor2">
      <hardwareInterface>EffortJointInterface</hardwareInterface>
      <mechanicalReduction>1</mechanicalReduction>
    </actuator>
  </transmission>  
  <transmission name="tran3">
    <type>transmission_interface/SimpleTransmission</type>
    <joint name="Left_wheel_03_link">
      <hardwareInterface>EffortJointInterface</hardwareInterface>
    </joint>
    <actuator name="motor3">
      <hardwareInterface>EffortJointInterface</hardwareInterface>
      <mechanicalReduction>1</mechanicalReduction>
    </actuator>
  </transmission>
  <transmission name="tran4">
    <type>transmission_interface/SimpleTransmission</type>
    <joint name="Left_wheel_01_link">
      <hardwareInterface>EffortJointInterface</hardwareInterface>
    </joint>
    <actuator name="motor4">
      <hardwareInterface>EffortJointInterface</hardwareInterface>
      <mechanicalReduction>1</mechanicalReduction>
    </actuator>
  </transmission>
  -->
</robot>

